2014-06-30 18:39:53,078 WARNING in /home/wangweiwei/test/trunk/nowdo/utils/session.py:24 :
Traceback (most recent call last):
  File "/home/wangweiwei/test/trunk/nowdo/utils/session.py", line 22, in session_cm
    yield session
  File "/home/wangweiwei/test/trunk/nowdo/forms/forms.py", line 51, in validate_email
    raise ValidationError(_(u'邮箱或帐号不存在'))
ValidationError: 邮箱或帐号不存在

2014-06-30 18:45:40,442 WARNING in /home/wangweiwei/test/trunk/nowdo/utils/session.py:24 :
Traceback (most recent call last):
  File "/home/wangweiwei/test/trunk/nowdo/utils/session.py", line 22, in session_cm
    yield session
  File "/home/wangweiwei/test/trunk/nowdo/views/task.py", line 356, in task_translate
    'id': str(current_user.id),
  File "/usr/local/lib/python2.7/dist-packages/werkzeug/local.py", line 336, in __getattr__
    return getattr(self._get_current_object(), name)
AttributeError: 'AnonymousUser' object has no attribute 'id'

